Traceback (most recent call last):
  File "D:\Users\jimzh\miniconda3\Lib\site-packages\jupyter_cache\executors\utils.py", line 58, in single_nb_execution
    executenb(
  File "D:\Users\jimzh\miniconda3\Lib\site-packages\nbclient\client.py", line 1314, in execute
    return NotebookClient(nb=nb, resources=resources, km=km, **kwargs).execute()
           ^^^^^^^^^^^^^^^^^^^^^^^^^^^^^^^^^^^^^^^^^^^^^^^^^^^^^^^^^^^^^^^^^^^^^
  File "C:\Users\jimzh\AppData\Roaming\Python\Python312\site-packages\jupyter_core\utils\__init__.py", line 165, in wrapped
    return loop.run_until_complete(inner)
           ^^^^^^^^^^^^^^^^^^^^^^^^^^^^^^
  File "D:\Users\jimzh\miniconda3\Lib\asyncio\base_events.py", line 687, in run_until_complete
    return future.result()
           ^^^^^^^^^^^^^^^
  File "D:\Users\jimzh\miniconda3\Lib\site-packages\nbclient\client.py", line 709, in async_execute
    await self.async_execute_cell(
  File "D:\Users\jimzh\miniconda3\Lib\site-packages\nbclient\client.py", line 1062, in async_execute_cell
    await self._check_raise_for_error(cell, cell_index, exec_reply)
  File "D:\Users\jimzh\miniconda3\Lib\site-packages\nbclient\client.py", line 918, in _check_raise_for_error
    raise CellExecutionError.from_cell_and_msg(cell, exec_reply_content)
nbclient.exceptions.CellExecutionError: An error occurred while executing the following cell:
------------------
sns.catplot(x='Pclass',data=titanic_df,hue='Sex',kind='count')
------------------


[1;31m---------------------------------------------------------------------------[0m
[1;31mNameError[0m                                 Traceback (most recent call last)
Cell [1;32mIn[4], line 1[0m
[1;32m----> 1[0m [43msns[49m[38;5;241m.[39mcatplot(x[38;5;241m=[39m[38;5;124m'[39m[38;5;124mPclass[39m[38;5;124m'[39m,data[38;5;241m=[39mtitanic_df,hue[38;5;241m=[39m[38;5;124m'[39m[38;5;124mSex[39m[38;5;124m'[39m,kind[38;5;241m=[39m[38;5;124m'[39m[38;5;124mcount[39m[38;5;124m'[39m)

[1;31mNameError[0m: name 'sns' is not defined

